Workbook

Sheet DADOS
B3: AMBIENTE | D3: TIPO IMPERMEABILIZAÇÃO | E3: PROTEÇÃO MECÂNICA | F3: PREPARAÇÃO SUPERFICIE
B4: INTERNA | D4: SISTEMA 1 | E4: NÃO | F4: SIM
B5: EXTERNA | D5: SISTEMA 2.1.4 | E5: NÃO | F5: SIM
D6: SISTEMA 2.5.3 | E6: NÃO | F6: SIM
D7: SISTEMA 2.8.6 | E7: NÃO | F7: SIM
D8: SISTEMA 4.2.4 | E8: SIM | F8: SIM
D9: SISTEMA 4.5.3 | E9: SIM | F9: SIM
D10: SISTEMA 4.9 | E10: SIM | F10: SIM
D11: SISTEMA 6.1.2 | E11: NÃO | F11: SIM
D12: SISTEMA 7.0.1 | E12: NÃO | F12: SIM
D13: SISTEMA 3.5.1 | E13: NÃO | F13: SIM
D14: SISTEMA 6.8.1 | E14: NÃO | F14: SIM
C19: LEGENDA DA IMPERMEABILIZAÇÃO
B22: Sistema 2.1.4 | C22: Argamassa polimérica para impermeabilização
B23: Sistema 2.5.3 | C23: Membrana de polímero acrílico com cimento e fibras sintéticas
B24: Sistema 2.8.6 | C24: Argamassa polimérica para impermeabilização + Membrana de polímero acrílico com cimento e fibras sintéticas
B25: Sistema 3.5.1 | C25: Membrana de polímero acrílico sem cimento
B26: Sistema 4.1.4 | C26: Manta asfáltica 4mm aderida com maçarico
B27: Sistema 4.2.4 | C27: Manta asfáltica 4mm aderida com asfalto oxidado modificado
B28: Sistema 4.5.3 | C28: Manta asfáltica 4mm aderida com asfalto oxidado modificado + Emulsão asfáltica antiraiz
B29: Sistema 6.1.2 | C29: Membrana impermeabilizante à base de poliuretano
B30: Sistema 6.8.1 | C30: Membrana impermeabilizante à base de epóxi poliamida

Sheet IMPERMEABILIZAÇÃO
B2: IMPERMEABILIZAÇÃO | K2: PAREDE | N2: PISO | Q2: CRONOGRAMA DE EXECUÇÃO
B3: TORRE | C3: PVTO | D3: LOCAL | E3: AMBIENTE | F3: INTERNA/EXTERNA | G3: LEGENDA SISTEMA | H3: TIPO IMPERMEABILIZAÇÃO | I3: PREPARAÇÃO SUPERFICIE | J3: PROTEÇÃO MECÂNICA | K3: ALTURA PAREDE (M) | L3: PERÍMETRO PAREDE (M) | M3: ÁREA PAREDE (M2) | N3: ÁREA PISO (M2) | O3: REPETIÇÕES | P3: ÁREA TOTAL (M2) | Q3: INICIO | R3: TÉRMINO
B4: EMBASAMENTO | C4: TÉRREO | D4: ÁREA COMUM | E4: RESERVATÓRIO - Cisterna 1 | F4: INTERNA | G4: SISTEMA 2.8.6 | H4: =VLOOKUP(G4,DADOS!$B$22:$C$30,2,TRUE) -> Argamassa polimérica para impermeabilização + Membrana de polímero acrílico com cimento e fibras sintéticas | I4: SIM | J4: NÃO | K4: 1.5 | L4: =14.15+14.15+1.9+1.9 -> 32.1 | M4: =L4*K4 -> 48.15 | N4: =14.15*1.9 -> 26.885 | O4: 1 | P4: =(M4+N4)*O4 -> 75.035 | Q4: 46216 | R4: =Q4+14 -> 46230
B5: EMBASAMENTO | C5: TÉRREO | D5: ÁREA COMUM | E5: RESERVATÓRIO - Cisterna 2 | F5: INTERNA | G5: SISTEMA 2.8.6 | H5: =VLOOKUP(G5,DADOS!$B$22:$C$30,2,TRUE) -> Argamassa polimérica para impermeabilização + Membrana de polímero acrílico com cimento e fibras sintéticas | I5: SIM | J5: NÃO | K5: 1.5 | L5: =14.15+14.15+1.9+1.9 -> 32.1 | M5: =L5*K5 -> 48.15 | N5: =14.15*1.9 -> 26.885 | O5: 1 | P5: =(M5+N5)*O5 -> 75.035 | Q5: 46216 | R5: =Q5+14 -> 46230
B6: EMBASAMENTO | C6: TÉRREO | D6: ÁREA COMUM | E6: RESERVATÓRIO - C. Cheias 1 | F6: INTERNA | G6: SISTEMA 2.8.6 | H6: =VLOOKUP(G6,DADOS!$B$22:$C$30,2,TRUE) -> Argamassa polimérica para impermeabilização + Membrana de polímero acrílico com cimento e fibras sintéticas | I6: SIM | J6: NÃO | K6: 1.2 | L6: =3.4+3.4+2.8+2.8 -> 12.4 | M6: =L6*K6 -> 14.88 | N6: =3.4*2.8 -> 9.52 | O6: 1 | P6: =(M6+N6)*O6 -> 24.4 | Q6: 46216 | R6: =Q6+14 -> 46230
B7: EMBASAMENTO | C7: TÉRREO | D7: ÁREA COMUM | E7: RESERVATÓRIO - C. Cheias 2 | F7: INTERNA | G7: SISTEMA 2.8.6 | H7: =VLOOKUP(G7,DADOS!$B$22:$C$30,2,TRUE) -> Argamassa polimérica para impermeabilização + Membrana de polímero acrílico com cimento e fibras sintéticas | I7: SIM | J7: NÃO | K7: 1.2 | L7: =3.4+3.4+2.8+2.8 -> 12.4 | M7: =L7*K7 -> 14.88 | N7: =3.4*2.8 -> 9.52 | O7: 1 | P7: =(M7+N7)*O7 -> 24.4 | Q7: 46216 | R7: =Q7+14 -> 46230
B8: EMBASAMENTO | C8: TÉRREO | D8: ÁREA COMUM | E8: RESERVATÓRIO - C. Cheias 3 | F8: INTERNA | G8: SISTEMA 2.8.6 | H8: =VLOOKUP(G8,DADOS!$B$22:$C$30,2,TRUE) -> Argamassa polimérica para impermeabilização + Membrana de polímero acrílico com cimento e fibras sintéticas | I8: SIM | J8: NÃO | K8: 1.2 | L8: =3.4+3.4+2.8+2.8 -> 12.4 | M8: =L8*K8 -> 14.88 | N8: =3.4*2.8 -> 9.52 | O8: 1 | P8: =(M8+N8)*O8 -> 24.4 | Q8: 46216 | R8: =Q8+14 -> 46230
B9: EMBASAMENTO | C9: TÉRREO | D9: ÁREA COMUM | E9: RESERVATÓRIO - C. Cheias 4 | F9: INTERNA | G9: SISTEMA 2.8.6 | H9: =VLOOKUP(G9,DADOS!$B$22:$C$30,2,TRUE) -> Argamassa polimérica para impermeabilização + Membrana de polímero acrílico com cimento e fibras sintéticas | I9: SIM | J9: NÃO | K9: 1.2 | L9: =3.4+3.4+2.8+2.8 -> 12.4 | M9: =L9*K9 -> 14.88 | N9: =3.4*2.8 -> 9.52 | O9: 1 | P9: =(M9+N9)*O9 -> 24.4 | Q9: 46216 | R9: =Q9+14 -> 46230
B10: EMBASAMENTO | C10: 3° PVTO | D10: ÁREA COMUM | E10: RESERVATÓRIO - Reuso | F10: INTERNA | G10: SISTEMA 2.8.6 | H10: =VLOOKUP(G10,DADOS!$B$22:$C$30,2,TRUE) -> Argamassa polimérica para impermeabilização + Membrana de polímero acrílico com cimento e fibras sintéticas | I10: SIM | J10: NÃO | K10: 2.75 | L10: 54.5873 | M10: 150.11507 | N10: 72.4052 | O10: 1 | P10: =(M10+N10)*O10 -> 222.52027 | Q10: 46216 | R10: =Q10+14 -> 46230
B11: EMBASAMENTO | C11: 3° PVTO | D11: ÁREA COMUM | E11: TETO DO RESERVATÓRIO - Reuso | F11: INTERNA | G11: SISTEMA 6.8.1 | H11: =VLOOKUP(G11,DADOS!$B$22:$C$30,2,TRUE) -> Membrana impermeabilizante à base de epóxi poliamida | I11: SIM | J11: NÃO | K11: 0 | L11: 0 | M11: 0 | N11: 72.4052 | O11: 1 | P11: =(M11+N11)*O11 -> 72.4052 | Q11: 46216 | R11: =Q11+14 -> 46230
B12: EMBASAMENTO | C12: 4º PVTO | D12: APTO FINAL 02 | E12: TERRAÇO PRIVATIVO | F12: EXTERNA | G12: SISTEMA 4.2.4 | H12: =VLOOKUP(G12,DADOS!$B$22:$C$30,2,TRUE) -> Manta asfáltica 4mm aderida com asfalto oxidado modificado | I12: SIM | J12: SIM | K12: 0.3 | L12: 19.275 | M12: 5.7825 | N12: 14.5937 | O12: 1 | P12: =(M12+N12)*O12 -> 20.3762 | Q12: 46252 | R12: =Q12+14 -> 46266
B13: EMBASAMENTO | C13: 4º PVTO | D13: APTO FINAL 03 | E13: TERRAÇO PRIVATIVO | F13: EXTERNA | G13: SISTEMA 4.2.4 | H13: =VLOOKUP(G13,DADOS!$B$22:$C$30,2,TRUE) -> Manta asfáltica 4mm aderida com asfalto oxidado modificado | I13: SIM | J13: SIM | K13: 0.3 | L13: 19.8361 | M13: 5.95083 | N13: 14.8153 | O13: 1 | P13: =(M13+N13)*O13 -> 20.76613 | Q13: 46252 | R13: =Q13+14 -> 46266
B14: EMBASAMENTO | C14: 4º PVTO | D14: APTO FINAL 04 | E14: TERRAÇO PRIVATIVO | F14: EXTERNA | G14: SISTEMA 4.2.4 | H14: =VLOOKUP(G14,DADOS!$B$22:$C$30,2,TRUE) -> Manta asfáltica 4mm aderida com asfalto oxidado modificado | I14: SIM | J14: SIM | K14: 0.3 | L14: 19.8361 | M14: 5.95083 | N14: 14.8153 | O14: 1 | P14: =(M14+N14)*O14 -> 20.76613 | Q14: 46252 | R14: =Q14+14 -> 46266
B15: EMBASAMENTO | C15: 4º PVTO | D15: APTO FINAL 05 | E15: TERRAÇO PRIVATIVO | F15: EXTERNA | G15: SISTEMA 4.2.4 | H15: =VLOOKUP(G15,DADOS!$B$22:$C$30,2,TRUE) -> Manta asfáltica 4mm aderida com asfalto oxidado modificado | I15: SIM | J15: SIM | K15: 0.3 | L15: 19.87 | M15: 5.961 | N15: 14.96 | O15: 1 | P15: =(M15+N15)*O15 -> 20.921 | Q15: 46252 | R15: =Q15+14 -> 46266
B16: EMBASAMENTO | C16: 4º PVTO | D16: APTO FINAL 06 | E16: TERRAÇO PRIVATIVO | F16: EXTERNA | G16: SISTEMA 4.2.4 | H16: =VLOOKUP(G16,DADOS!$B$22:$C$30,2,TRUE) -> Manta asfáltica 4mm aderida com asfalto oxidado modificado | I16: SIM | J16: SIM | K16: 0.3 | L16: 19.866 | M16: 5.9598 | N16: 14.9631 | O16: 1 | P16: =(M16+N16)*O16 -> 20.9229 | Q16: 46252 | R16: =Q16+14 -> 46266
B17: EMBASAMENTO | C17: 4º PVTO | D17: APTO FINAL 07 | E17: TERRAÇO PRIVATIVO | F17: EXTERNA | G17: SISTEMA 4.2.4 | H17: =VLOOKUP(G17,DADOS!$B$22:$C$30,2,TRUE) -> Manta asfáltica 4mm aderida com asfalto oxidado modificado | I17: SIM | J17: SIM | K17: 0.3 | L17: 20.0674 | M17: 6.02022 | N17: 13.2513 | O17: 1 | P17: =(M17+N17)*O17 -> 19.27152 | Q17: 46252 | R17: =Q17+14 -> 46266
B18: EMBASAMENTO | C18: 4º PVTO | D18: APTO FINAL 05 | E18: TERRAÇO PRIVATIVO | F18: EXTERNA | G18: SISTEMA 4.2.4 | H18: =VLOOKUP(G18,DADOS!$B$22:$C$30,2,TRUE) -> Manta asfáltica 4mm aderida com asfalto oxidado modificado | I18: SIM | J18: SIM | K18: 0.3 | L18: 20.225 | M18: 6.0675 | N18: 13.4134 | O18: 1 | P18: =(M18+N18)*O18 -> 19.4809 | Q18: 46252 | R18: =Q18+14 -> 46266
B19: EMBASAMENTO | C19: 4º PVTO | D19: APTO FINAL 06 | E19: TERRAÇO PRIVATIVO | F19: EXTERNA | G19: SISTEMA 4.2.4 | H19: =VLOOKUP(G19,DADOS!$B$22:$C$30,2,TRUE) -> Manta asfáltica 4mm aderida com asfalto oxidado modificado | I19: SIM | J19: SIM | K19: 0.3 | L19: 19.8176 | M19: 5.94528 | N19: 14.9776 | O19: 1 | P19: =(M19+N19)*O19 -> 20.92288 | Q19: 46252 | R19: =Q19+14 -> 46266
B20: EMBASAMENTO | C20: 4º PVTO | D20: APTO FINAL 07 | E20: TERRAÇO PRIVATIVO | F20: EXTERNA | G20: SISTEMA 4.2.4 | H20: =VLOOKUP(G20,DADOS!$B$22:$C$30,2,TRUE) -> Manta asfáltica 4mm aderida com asfalto oxidado modificado | I20: SIM | J20: SIM | K20: 0.3 | L20: 19.8376 | M20: 5.95128 | N20: 14.977 | O20: 1 | P20: =(M20+N20)*O20 -> 20.92828 | Q20: 46252 | R20: =Q20+14 -> 46266
B21: EMBASAMENTO | C21: 4º PVTO | D21: APTO FINAL 08 | E21: TERRAÇO PRIVATIVO | F21: EXTERNA | G21: SISTEMA 4.2.4 | H21: =VLOOKUP(G21,DADOS!$B$22:$C$30,2,TRUE) -> Manta asfáltica 4mm aderida com asfalto oxidado modificado | I21: SIM | J21: SIM | K21: 0.3 | L21: 19.8076 | M21: 5.94228 | N21: 14.9421 | O21: 1 | P21: =(M21+N21)*O21 -> 20.88438 | Q21: 46252 | R21: =Q21+14 -> 46266
... B25: EMBASAMENTO | C25: 4º PVTO | D25: APTO FINAL 12 | E25: TERRAÇO PRIVATIVO | F25: EXTERNA | G25: SISTEMA 4.2.4 | H25: =VLOOKUP(G25,DADOS!$B$22:$C$30,2,TRUE) -> Manta asfáltica 4mm aderida com asfalto oxidado modificado | I25: SIM | J25: SIM | K25: 0.3 | L25: 20.315 | M25: 6.0945 | N25: 13.4384 | O25: 1 | P25: =(M25+N25)*O25 -> 19.5329 | Q25: 46252 | R25: =Q25+14 -> 46266
B26: EMBASAMENTO | C26: 4º PVTO | D26: ÁREA EXTERNA | E26: FLOREIRA | F26: EXTERNA | G26: SISTEMA 4.5.3 | H26: =VLOOKUP(G26,DADOS!$B$22:$C$30,2,TRUE) -> Manta asfáltica 4mm aderida com asfalto oxidado modificado + Emulsão asfáltica antiraiz | I26: SIM | J26: SIM | K26: 0.5 | L26: 13.9886 | M26: 6.9943 | N26: 8.9886 | O26: 1 | P26: =(M26+N26)*O26 -> 15.9829 | Q26: 46281 | R26: =Q26+30 -> 46311
B27: EMBASAMENTO | C27: 4º PVTO | D27: ÁREA EXTERNA | E27: FLOREIRA | F27: EXTERNA | G27: SISTEMA 4.5.3 | H27: =VLOOKUP(G27,DADOS!$B$22:$C$30,2,TRUE) -> Manta asfáltica 4mm aderida com asfalto oxidado modificado + Emulsão asfáltica antiraiz | I27: SIM | J27: SIM | K27: 0.5 | L27: 39.9868 | M27: 19.9934 | N27: 11.4743 | O27: 1 | P27: =(M27+N27)*O27 -> 31.4677 | Q27: 46281 | R27: =Q27+30 -> 46311
B28: EMBASAMENTO | C28: 4º PVTO | D28: ÁREA EXTERNA | E28: FLOREIRA | F28: EXTERNA | G28: SISTEMA 4.5.3 | H28: =VLOOKUP(G28,DADOS!$B$22:$C$30,2,TRUE) -> Manta asfáltica 4mm aderida com asfalto oxidado modificado + Emulsão asfáltica antiraiz | I28: SIM | J28: SIM | K28: 0.5 | L28: 10.5496 | M28: 5.2748 | N28: 4.9525 | O28: 1 | P28: =(M28+N28)*O28 -> 10.2273 | Q28: 46281 | R28: =Q28+30 -> 46311
B29: EMBASAMENTO | C29: 4º PVTO | D29: ÁREA EXTERNA | E29: FLOREIRA | F29: EXTERNA | G29: SISTEMA 4.5.3 | H29: =VLOOKUP(G29,DADOS!$B$22:$C$30,2,TRUE) -> Manta asfáltica 4mm aderida com asfalto oxidado modificado + Emulsão asfáltica antiraiz | I29: SIM | J29: SIM | K29: 0.5 | L29: 10.2283 | M29: 5.11415 | N29: 3.2379 | O29: 1 | P29: =(M29+N29)*O29 -> 8.35205 | Q29: 46281 | R29: =Q29+30 -> 46311
B30: EMBASAMENTO | C30: 4º PVTO | D30: ÁREA EXTERNA | E30: FLOREIRA | F30: EXTERNA | G30: SISTEMA 4.5.3 | H30: =VLOOKUP(G30,DADOS!$B$22:$C$30,2,TRUE) -> Manta asfáltica 4mm aderida com asfalto oxidado modificado + Emulsão asfáltica antiraiz | I30: SIM | J30: SIM | K30: 0.5 | L30: 11.3747 | M30: 5.68735 | N30: 3.5338 | O30: 1 | P30: =(M30+N30)*O30 -> 9.22115 | Q30: 46281 | R30: =Q30+30 -> 46311
B31: EMBASAMENTO | C31: 4º PVTO | D31: ÁREA EXTERNA | E31: FLOREIRA | F31: EXTERNA | G31: SISTEMA 4.5.3 | H31: =VLOOKUP(G31,DADOS!$B$22:$C$30,2,TRUE) -> Manta asfáltica 4mm aderida com asfalto oxidado modificado + Emulsão asfáltica antiraiz | I31: SIM | J31: SIM | K31: 0.5 | L31: 13.798 | M31: 6.899 | N31: 2.4859 | O31: 1 | P31: =(M31+N31)*O31 -> 9.3849 | Q31: 46281 | R31: =Q31+30 -> 46311
B32: EMBASAMENTO | C32: 4º PVTO | D32: ÁREA EXTERNA | E32: FLOREIRA | F32: EXTERNA | G32: SISTEMA 4.5.3 | H32: =VLOOKUP(G32,DADOS!$B$22:$C$30,2,TRUE) -> Manta asfáltica 4mm aderida com asfalto oxidado modificado + Emulsão asfáltica antiraiz | I32: SIM | J32: SIM | K32: 0.5 | L32: 19.9367 | M32: 9.96835 | N32: 3.7236 | O32: 1 | P32: =(M32+N32)*O32 -> 13.69195 | Q32: 46281 | R32: =Q32+30 -> 46311
B33: EMBASAMENTO | C33: 4º PVTO | D33: ÁREA EXTERNA | E33: FLOREIRA | F33: EXTERNA | G33: SISTEMA 4.5.3 | H33: =VLOOKUP(G33,DADOS!$B$22:$C$30,2,TRUE) -> Manta asfáltica 4mm aderida com asfalto oxidado modificado + Emulsão asfáltica antiraiz | I33: SIM | J33: SIM | K33: 0.5 | L33: 10.9866 | M33: 5.4933 | N33: 5.2343 | O33: 1 | P33: =(M33+N33)*O33 -> 10.7276 | Q33: 46281 | R33: =Q33+30 -> 46311
B34: EMBASAMENTO | C34: 4º PVTO | D34: ÁREA EXTERNA | E34: FLOREIRA | F34: EXTERNA | G34: SISTEMA 4.5.3 | H34: =VLOOKUP(G34,DADOS!$B$22:$C$30,2,TRUE) -> Manta asfáltica 4mm aderida com asfalto oxidado modificado + Emulsão asfáltica antiraiz | I34: SIM | J34: SIM | K34: 0.5 | L34: 23.1358 | M34: 11.5679 | N34: 6.7652 | O34: 1 | P34: =(M34+N34)*O34 -> 18.3331 | Q34: 46281 | R34: =Q34+30 -> 46311
B35: EMBASAMENTO | C35: 4º PVTO | D35: ÁREA EXTERNA | E35: FLOREIRA | F35: EXTERNA | G35: SISTEMA 4.5.3 | H35: =VLOOKUP(G35,DADOS!$B$22:$C$30,2,TRUE) -> Manta asfáltica 4mm aderida com asfalto oxidado modificado + Emulsão asfáltica antiraiz | I35: SIM | J35: SIM | K35: 0.5 | L35: 15.7615 | M35: 7.88075 | N35: 5.157 | O35: 1 | P35: =(M35+N35)*O35 -> 13.03775 | Q35: 46281 | R35: =Q35+30 -> 46311
B36: EMBASAMENTO | C36: 4º PVTO | D36: ÁREA EXTERNA | E36: FLOREIRA | F36: EXTERNA | G36: SISTEMA 4.5.3 | H36: =VLOOKUP(G36,DADOS!$B$22:$C$30,2,TRUE) -> Manta asfáltica 4mm aderida com asfalto oxidado modificado + Emulsão asfáltica antiraiz | I36: SIM | J36: SIM | K36: 0.5 | L36: 11.0505 | M36: 5.52525 | N36: 5.0331 | O36: 1 | P36: =(M36+N36)*O36 -> 10.55835 | Q36: 46281 | R36: =Q36+30 -> 46311
B37: EMBASAMENTO | C37: 4º PVTO | D37: ÁREA EXTERNA | E37: FLOREIRA | F37: EXTERNA | G37: SISTEMA 4.5.3 | H37: =VLOOKUP(G37,DADOS!$B$22:$C$30,2,TRUE) -> Manta asfáltica 4mm aderida com asfalto oxidado modificado + Emulsão asfáltica antiraiz | I37: SIM | J37: SIM | K37: 0.5 | L37: 11.1839 | M37: 5.59195 | N37: 4.2835 | O37: 1 | P37: =(M37+N37)*O37 -> 9.87545 | Q37: 46281 | R37: =Q37+30 -> 46311
... B55: EMBASAMENTO | C55: 4º PVTO | D55: ÁREA EXTERNA | E55: CIRCULAÇÃO | F55: EXTERNA | G55: SISTEMA 4.2.4 | H55: =VLOOKUP(G55,DADOS!$B$22:$C$30,2,TRUE) -> Manta asfáltica 4mm aderida com asfalto oxidado modificado | I55: SIM | J55: SIM | K55: 0.3 | L55: 814.48038 | M55: 244.34411 | N55: 1586.8586 | O55: 1 | P55: =(M55+N55)*O55 -> 1831.2027 | Q55: 46281 | R55: =Q55+30 -> 46311
B56: BLOCO 01 | C56: COBERTURA | D56: ÁREA COMUM | E56: RESERVATÓRIO | F56: INTERNA | G56: SISTEMA 2.8.6 | H56: =VLOOKUP(G56,DADOS!$B$22:$C$30,2,TRUE) -> Argamassa polimérica para impermeabilização + Membrana de polímero acrílico com cimento e fibras sintéticas | I56: SIM | J56: NÃO | K56: 2.8 | L56: 18.56 | M56: 51.968 | N56: 20.78 | O56: 1 | P56: =(M56+N56)*O56 -> 72.748 | Q56: 46398 | R56: =Q56+14 -> 46412
B57: BLOCO 01 | C57: COBERTURA | D57: ÁREA COMUM | E57: RESERVATÓRIO | F57: INTERNA | G57: SISTEMA 2.8.6 | H57: =VLOOKUP(G57,DADOS!$B$22:$C$30,2,TRUE) -> Argamassa polimérica para impermeabilização + Membrana de polímero acrílico com cimento e fibras sintéticas | I57: SIM | J57: NÃO | K57: 2.8 | L57: 18.31 | M57: 51.268 | N57: 20.298 | O57: 1 | P57: =(M57+N57)*O57 -> 71.566 | Q57: 46398 | R57: =Q57+14 -> 46412
B58: BLOCO 01 | C58: COBERTURA | D58: ÁREA COMUM | E58: TETO DO RESERVATÓRIO | F58: INTERNA | G58: SISTEMA 6.8.1 | H58: =VLOOKUP(G58,DADOS!$B$22:$C$30,2,TRUE) -> Membrana impermeabilizante à base de epóxi poliamida | I58: SIM | J58: NÃO | K58: 2.8 | L58: 0 | M58: 0 | N58: 22.55 | O58: 1 | P58: =(M58+N58)*O58 -> 22.55 | Q58: 46398 | R58: =Q58+14 -> 46412
B59: BLOCO 02 | C59: COBERTURA | D59: ÁREA COMUM | E59: RESERVATÓRIO | F59: INTERNA | G59: SISTEMA 2.8.6 | H59: =VLOOKUP(G59,DADOS!$B$22:$C$30,2,TRUE) -> Argamassa polimérica para impermeabilização + Membrana de polímero acrílico com cimento e fibras sintéticas | I59: SIM | J59: NÃO | K59: 2.8 | L59: 22.61 | M59: 63.308 | N59: 22.55 | O59: 1 | P59: =(M59+N59)*O59 -> 85.858 | Q59: 46398 | R59: =Q59+14 -> 46412
B60: BLOCO 02 | C60: COBERTURA | D60: ÁREA COMUM | E60: TETO DO RESERVATÓRIO | F60: INTERNA | G60: SISTEMA 6.8.1 | H60: =VLOOKUP(G60,DADOS!$B$22:$C$30,2,TRUE) -> Membrana impermeabilizante à base de epóxi poliamida | I60: SIM | J60: NÃO | K60: 2.8 | L60: 0 | M60: 0 | N60: 22.81 | O60: 1 | P60: =(M60+N60)*O60 -> 22.81 | Q60: 46398 | R60: =Q60+14 -> 46412
B61: BLOCO 02 | C61: COBERTURA | D61: ÁREA COMUM | E61: RESERVATÓRIO | F61: INTERNA | G61: SISTEMA 2.8.6 | H61: =VLOOKUP(G61,DADOS!$B$22:$C$30,2,TRUE) -> Argamassa polimérica para impermeabilização + Membrana de polímero acrílico com cimento e fibras sintéticas | I61: SIM | J61: NÃO | K61: 2.8 | L61: 22.61 | M61: 63.308 | N61: 22.55 | O61: 1 | P61: =(M61+N61)*O61 -> 85.858 | Q61: 46398 | R61: =Q61+14 -> 46412
...

Sheet IMPER JANELAS
B3: IMPERMEABILIZAÇÃO JANELAS E PORTAS
B4: PVTO | C4: LOCAL | D4: CÓD. PROJETO | E4: ELEMENTO | F4: QUANT. PVTO | G4: REPETIÇÕES | H4: QUANT. TOTAL | I4: LARG. (M) | J4: ALT.(M) | K4: ESPESSURA (M) | L4: IMPERMEABILIZAÇÃO (m2)
B5: TÉRREO | C5: EMBASAMENTO | D5: J02 | E5: JANELA | F5: 5 | G5: 1 | H5: =G5*F5 -> 5 | I5: =VLOOKUP(D5,'[1]RESUMO ESQ. '!$E$6:$L$71,5,FALSE) -> 0.5 | J5: =VLOOKUP(D5,'[1]RESUMO ESQ. '!$E$6:$L$71,6,FALSE) -> 0.61 | K5: 0.19 | L5: =((I5*K5)+(2*0.1*K5))*H5 -> 0.665
B6: TÉRREO | C6: EMBASAMENTO | D6: J03 | E6: JANELA | F6: 1 | G6: 1 | H6: =G6*F6 -> 1 | I6: =VLOOKUP(D6,'[1]RESUMO ESQ. '!$E$6:$L$71,5,FALSE) -> 1.1 | J6: =VLOOKUP(D6,'[1]RESUMO ESQ. '!$E$6:$L$71,6,FALSE) -> 0.8 | K6: 0.19 | L6: =((I6*K6)+(2*0.1*K6))*H6 -> 0.247
B7: TÉRREO | C7: EMBASAMENTO | D7: J07 | E7: JANELA | F7: 2 | G7: 1 | H7: =G7*F7 -> 2 | I7: =VLOOKUP(D7,'[1]RESUMO ESQ. '!$E$6:$L$71,5,FALSE) -> 2 | J7: =VLOOKUP(D7,'[1]RESUMO ESQ. '!$E$6:$L$71,6,FALSE) -> 1.4 | K7: 0.19 | L7: =((I7*K7)+(2*0.1*K7))*H7 -> 0.836
B8: TÉRREO | C8: EMBASAMENTO | D8: J10 | E8: JANELA | F8: 1 | G8: 1 | H8: =G8*F8 -> 1 | I8: =VLOOKUP(D8,'[1]RESUMO ESQ. '!$E$6:$L$71,5,FALSE) -> 5 | J8: =VLOOKUP(D8,'[1]RESUMO ESQ. '!$E$6:$L$71,6,FALSE) -> 2.05 | K8: 0.19 | L8: =((I8*K8)+(2*0.1*K8))*H8 -> 0.988
B9: TÉRREO | C9: EMBASAMENTO | D9: PJ07 | E9: PORTA | F9: 2 | G9: 1 | H9: =G9*F9 -> 2 | I9: =VLOOKUP(D9,'[1]RESUMO ESQ. '!$E$6:$L$71,5,FALSE) -> 1.86 | J9: =VLOOKUP(D9,'[1]RESUMO ESQ. '!$E$6:$L$71,6,FALSE) -> 2.5 | K9: 0.19 | L9: =((I9*K9)+(2*0.1*K9))*H9 -> 0.7828
B10: TÉRREO | C10: EMBASAMENTO | D10: PJ12 | E10: PORTA | F10: 1 | G10: 1 | H10: =G10*F10 -> 1 | I10: =VLOOKUP(D10,'[1]RESUMO ESQ. '!$E$6:$L$71,5,FALSE) -> 3 | J10: =VLOOKUP(D10,'[1]RESUMO ESQ. '!$E$6:$L$71,6,FALSE) -> 2.1 | K10: 0.19 | L10: =((I10*K10)+(2*0.1*K10))*H10 -> 0.608
B11: TÉRREO | C11: EMBASAMENTO | D11: PJ14 | E11: PORTA | F11: 2 | G11: 1 | H11: =G11*F11 -> 2 | I11: =VLOOKUP(D11,'[1]RESUMO ESQ. '!$E$6:$L$71,5,FALSE) -> 0.96 | J11: =VLOOKUP(D11,'[1]RESUMO ESQ. '!$E$6:$L$71,6,FALSE) -> 2.5 | K11: 0.19 | L11: =((I11*K11)+(2*0.1*K11))*H11 -> 0.4408
B12: TÉRREO | C12: EMBASAMENTO | D12: PA01 | E12: PORTA | F12: 4 | G12: 1 | H12: =G12*F12 -> 4 | I12: =VLOOKUP(D12,'[1]RESUMO ESQ. '!$E$6:$L$71,5,FALSE) -> 0.96 | J12: =VLOOKUP(D12,'[1]RESUMO ESQ. '!$E$6:$L$71,6,FALSE) -> 2.13 | K12: 0.205 | L12: =((I12*K12)+(2*0.1*K12))*H12 -> 0.9512
B13: TÉRREO | C13: EMBASAMENTO | D13: PA02 | E13: PORTA | F13: 1 | G13: 1 | H13: =G13*F13 -> 1 | I13: =VLOOKUP(D13,'[1]RESUMO ESQ. '!$E$6:$L$71,5,FALSE) -> 1.06 | J13: =VLOOKUP(D13,'[1]RESUMO ESQ. '!$E$6:$L$71,6,FALSE) -> 2.13 | K13: 0.205 | L13: =((I13*K13)+(2*0.1*K13))*H13 -> 0.2583
B14: TÉRREO | C14: EMBASAMENTO | D14: PA03 | E14: PORTA | F14: 1 | G14: 1 | H14: =G14*F14 -> 1 | I14: =VLOOKUP(D14,'[1]RESUMO ESQ. '!$E$6:$L$71,5,FALSE) -> 0.86 | J14: =VLOOKUP(D14,'[1]RESUMO ESQ. '!$E$6:$L$71,6,FALSE) -> 2.13 | K14: 0.205 | L14: =((I14*K14)+(2*0.1*K14))*H14 -> 0.2173
B15: TÉRREO | C15: EMBASAMENTO | D15: PA04 | E15: PORTA | F15: 1 | G15: 1 | H15: =G15*F15 -> 1 | I15: =VLOOKUP(D15,'[1]RESUMO ESQ. '!$E$6:$L$71,5,FALSE) -> 0.96 | J15: =VLOOKUP(D15,'[1]RESUMO ESQ. '!$E$6:$L$71,6,FALSE) -> 2.13 | K15: 0.205 | L15: =((I15*K15)+(2*0.1*K15))*H15 -> 0.2378
B16: TÉRREO | C16: EMBASAMENTO | D16: PM01 | E16: PORTA | F16: 2 | G16: 1 | H16: =G16*F16 -> 2 | I16: =VLOOKUP(D16,'[1]RESUMO ESQ. '!$E$6:$L$71,5,FALSE) -> 0.6 | J16: =VLOOKUP(D16,'[1]RESUMO ESQ. '!$E$6:$L$71,6,FALSE) -> 2.1 | K16: 0.19 | L16: =((I16*K16)+(2*0.1*K16))*H16 -> 0.304
... B20: TÉRREO | C20: EMBASAMENTO | D20: PO01 | E20: PORTÃO | F20: 2 | G20: 1 | H20: =G20*F20 -> 2 | I20: =VLOOKUP(D20,'[1]RESUMO ESQ. '!$E$6:$L$71,5,FALSE) -> 5 | J20: =VLOOKUP(D20,'[1]RESUMO ESQ. '!$E$6:$L$71,6,FALSE) -> 2.5 | K20: 0.19 | L20: =((I20*K20)+(2*0.1*K20))*H20 -> 1.976
B21: TÉRREO | C21: EMBASAMENTO | D21: PV03 | E21: =VLOOKUP(D21,'[1]RESUMO ESQ. '!$E$5:$L$76,2,FALSE) -> PORTA | F21: 1 | G21: 1 | H21: =F21*G21 -> 1 | I21: =VLOOKUP(D21,'[1]RESUMO ESQ. '!$E$6:$L$71,5,FALSE) -> 0.7 | J21: =VLOOKUP(D21,'[1]RESUMO ESQ. '!$E$6:$L$71,6,FALSE) -> 2.1 | K21: 0.19 | L21: =((I21*K21)+(2*0.1*K21))*H21 -> 0.171
B22: TÉRREO | C22: EMBASAMENTO | D22: PV02 | E22: =VLOOKUP(D22,'[1]RESUMO ESQ. '!$E$5:$L$76,2,FALSE) -> PORTA | F22: 1 | G22: 1 | H22: =F22*G22 -> 1 | I22: =VLOOKUP(D22,'[1]RESUMO ESQ. '!$E$6:$L$71,5,FALSE) -> 0.7 | J22: =VLOOKUP(D22,'[1]RESUMO ESQ. '!$E$6:$L$71,6,FALSE) -> 0.9 | K22: 0.19 | L22: =((I22*K22)+(2*0.1*K22))*H22 -> 0.171
B23: TÉRREO | C23: EMBASAMENTO | D23: PV05 | E23: =VLOOKUP(D23,'[1]RESUMO ESQ. '!$E$5:$L$76,2,FALSE) -> PORTA | F23: 1 | G23: 1 | H23: =F23*G23 -> 1 | I23: =VLOOKUP(D23,'[1]RESUMO ESQ. '!$E$6:$L$71,5,FALSE) -> 1 | J23: =VLOOKUP(D23,'[1]RESUMO ESQ. '!$E$6:$L$71,6,FALSE) -> 2.1 | K23: 0.165 | L23: =((I23*K23)+(2*0.1*K23))*H23 -> 0.198
B24: TÉRREO | C24: EMBASAMENTO | D24: PV06 | E24: =VLOOKUP(D24,'[1]RESUMO ESQ. '!$E$5:$L$76,2,FALSE) -> PORTA | F24: 4 | G24: 1 | H24: =F24*G24 -> 4 | I24: =VLOOKUP(D24,'[1]RESUMO ESQ. '!$E$6:$L$71,5,FALSE) -> 1 | J24: =VLOOKUP(D24,'[1]RESUMO ESQ. '!$E$6:$L$71,6,FALSE) -> 2.1 | K24: 0.205 | L24: =((I24*K24)+(2*0.1*K24))*H24 -> 0.984
B25: TÉRREO | C25: EMBASAMENTO | D25: PV08 | E25: =VLOOKUP(D25,'[1]RESUMO ESQ. '!$E$5:$L$76,2,FALSE) -> PORTA | F25: 1 | G25: 1 | H25: =F25*G25 -> 1 | I25: =VLOOKUP(D25,'[1]RESUMO ESQ. '!$E$6:$L$71,5,FALSE) -> 1.5 | J25: =VLOOKUP(D25,'[1]RESUMO ESQ. '!$E$6:$L$71,6,FALSE) -> 2.1 | K25: 0.19 | L25: =((I25*K25)+(2*0.1*K25))*H25 -> 0.323
B26: TÉRREO | C26: EMBASAMENTO | D26: PV09 | E26: =VLOOKUP(D26,'[1]RESUMO ESQ. '!$E$5:$L$76,2,FALSE) -> PORTA | F26: 3 | G26: 1 | H26: =F26*G26 -> 3 | I26: =VLOOKUP(D26,'[1]RESUMO ESQ. '!$E$6:$L$71,5,FALSE) -> 1.8 | J26: =VLOOKUP(D26,'[1]RESUMO ESQ. '!$E$6:$L$71,6,FALSE) -> 2.1 | K26: 0.205 | L26: =((I26*K26)+(2*0.1*K26))*H26 -> 1.23
B27: TÉRREO | C27: EMBASAMENTO | D27: PV10 | E27: =VLOOKUP(D27,'[1]RESUMO ESQ. '!$E$5:$L$76,2,FALSE) -> PORTA | F27: 1 | G27: 1 | H27: =F27*G27 -> 1 | I27: =VLOOKUP(D27,'[1]RESUMO ESQ. '!$E$6:$L$71,5,FALSE) -> 1.9 | J27: =VLOOKUP(D27,'[1]RESUMO ESQ. '!$E$6:$L$71,6,FALSE) -> 0.95 | K27: 0.18 | L27: =((I27*K27)+(2*0.1*K27))*H27 -> 0.378
B28: TÉRREO | C28: EMBASAMENTO | D28: V02 | E28: =VLOOKUP(D28,'[1]RESUMO ESQ. '!$E$5:$L$76,2,FALSE) -> VENEZIANA | F28: 1 | G28: 1 | H28: =F28*G28 -> 1 | I28: =VLOOKUP(D28,'[1]RESUMO ESQ. '!$E$6:$L$71,5,FALSE) -> 0.25 | J28: =VLOOKUP(D28,'[1]RESUMO ESQ. '!$E$6:$L$71,6,FALSE) -> 0.25 | K28: 0.19 | L28: =((I28*K28)+(2*0.1*K28))*H28 -> 0.0855
B29: TÉRREO | C29: EMBASAMENTO | D29: V03 | E29: =VLOOKUP(D29,'[1]RESUMO ESQ. '!$E$5:$L$76,2,FALSE) -> VENEZIANA | F29: 1 | G29: 1 | H29: =F29*G29 -> 1 | I29: =VLOOKUP(D29,'[1]RESUMO ESQ. '!$E$6:$L$71,5,FALSE) -> 0.3 | J29: =VLOOKUP(D29,'[1]RESUMO ESQ. '!$E$6:$L$71,6,FALSE) -> 0.5 | K29: 0.21 | L29: =((I29*K29)+(2*0.1*K29))*H29 -> 0.105
B30: 2º PAVIMENTO | C30: EMBASAMENTO | D30: PV07 | E30: =VLOOKUP(D30,'[1]RESUMO ESQ. '!$E$5:$L$76,2,FALSE) -> PORTA | F30: 1 | G30: 1 | H30: =F30*G30 -> 1 | I30: =VLOOKUP(D30,'[1]RESUMO ESQ. '!$E$6:$L$71,5,FALSE) -> 1.2 | J30: =VLOOKUP(D30,'[1]RESUMO ESQ. '!$E$6:$L$71,6,FALSE) -> 2.1 | K30: 0.19 | L30: =((I30*K30)+(2*0.1*K30))*H30 -> 0.266
B31: 2º PAVIMENTO | C31: EMBASAMENTO | D31: V12 | E31: =VLOOKUP(D31,'[1]RESUMO ESQ. '!$E$5:$L$76,2,FALSE) -> VENEZIANA | F31: 3 | G31: 1 | H31: =F31*G31 -> 3 | I31: =VLOOKUP(D31,'[1]RESUMO ESQ. '!$E$6:$L$71,5,FALSE) -> 3 | J31: =VLOOKUP(D31,'[1]RESUMO ESQ. '!$E$6:$L$71,6,FALSE) -> 1.8 | K31: 0.19 | L31: =((I31*K31)+(2*0.1*K31))*H31 -> 1.824
B32: 2º PAVIMENTO | C32: EMBASAMENTO | D32: PA01 | E32: =VLOOKUP(D32,'[1]RESUMO ESQ. '!$E$5:$L$76,2,FALSE) -> PORTA | F32: 1 | G32: 1 | H32: =F32*G32 -> 1 | I32: =VLOOKUP(D32,'[1]RESUMO ESQ. '!$E$6:$L$71,5,FALSE) -> 0.96 | J32: =VLOOKUP(D32,'[1]RESUMO ESQ. '!$E$6:$L$71,6,FALSE) -> 2.13 | K32: 0.19 | L32: =((I32*K32)+(2*0.1*K32))*H32 -> 0.2204
... B34: 2º PAVIMENTO | C34: EMBASAMENTO | D34: PM04 | E34: =VLOOKUP(D34,'[1]RESUMO ESQ. '!$E$5:$L$76,2,FALSE) -> PORTA | F34: 1 | G34: 1 | H34: =F34*G34 -> 1 | I34: =VLOOKUP(D34,'[1]RESUMO ESQ. '!$E$6:$L$71,5,FALSE) -> 0.9 | J34: =VLOOKUP(D34,'[1]RESUMO ESQ. '!$E$6:$L$71,6,FALSE) -> 2.1 | K34: 0.19 | L34: =((I34*K34)+(2*0.1*K34))*H34 -> 0.209
B35: 3º PAVIMENTO | C35: EMBASAMENTO | D35: PV04 | E35: =VLOOKUP(D35,'[1]RESUMO ESQ. '!$E$5:$L$76,2,FALSE) -> PORTA | F35: 1 | G35: 1 | H35: =G35*F35 -> 1 | I35: 0.9 | J35: 2.1 | K35: 0.19 | L35: =((I35*K35)+(2*0.1*K35))*H35 -> 0.209
B36: 3º PAVIMENTO | C36: EMBASAMENTO | D36: PV07 | E36: =VLOOKUP(D36,'[1]RESUMO ESQ. '!$E$5:$L$76,2,FALSE) -> PORTA | F36: 1 | G36: 1 | H36: =G36*F36 -> 1 | I36: 1.2 | J36: 2.1 | K36: 0.14 | L36: =((I36*K36)+(2*0.1*K36))*H36 -> 0.196
B37: 3º PAVIMENTO | C37: EMBASAMENTO | D37: PV11 | E37: =VLOOKUP(D37,'[1]RESUMO ESQ. '!$E$5:$L$76,2,FALSE) -> PORTA | F37: 2 | G37: 1 | H37: =G37*F37 -> 2 | I37: 1.2 | J37: 2.1 | K37: 0.24 | L37: =((I37*K37)+(2*0.1*K37))*H37 -> 0.672
B38: 3º PAVIMENTO | C38: EMBASAMENTO | D38: V04 | E38: VENEZIANA | F38: 1 | G38: 1 | H38: =G38*F38 -> 1 | I38: 1 | J38: 0.5 | K38: 0.24 | L38: =((I38*K38)+(2*0.1*K38))*H38 -> 0.288
B39: 3º PAVIMENTO | C39: EMBASAMENTO | D39: V06 | E39: VENEZIANA | F39: 1 | G39: 1 | H39: =G39*F39 -> 1 | I39: 1.5 | J39: 0.8 | K39: 0.215 | L39: =((I39*K39)+(2*0.1*K39))*H39 -> 0.3655
B40: 3º PAVIMENTO | C40: EMBASAMENTO | D40: V09 | E40: VENEZIANA | F40: 1 | G40: 1 | H40: =G40*F40 -> 1 | I40: 2 | J40: 1.8 | K40: 0.205 | L40: =((I40*K40)+(2*0.1*K40))*H40 -> 0.451
B41: 3º PAVIMENTO | C41: EMBASAMENTO | D41: V12 | E41: VENEZIANA | F41: 1 | G41: 1 | H41: =G41*F41 -> 1 | I41: 3 | J41: 1.8 | K41: 0.205 | L41: =((I41*K41)+(2*0.1*K41))*H41 -> 0.656
B42: 3º PAVIMENTO | C42: EMBASAMENTO | D42: V15 | E42: VENEZIANA | F42: 2 | G42: 1 | H42: =G42*F42 -> 2 | I42: 2.75 | J42: 1.5 | K42: 0.205 | L42: =((I42*K42)+(2*0.1*K42))*H42 -> 1.2095
B43: 3º PAVIMENTO | C43: EMBASAMENTO | D43: V16 | E43: VENEZIANA | F43: 4 | G43: 1 | H43: =G43*F43 -> 4 | I43: 3.25 | J43: 2.25 | K43: 0.205 | L43: =((I43*K43)+(2*0.1*K43))*H43 -> 2.829
B44: 3º PAVIMENTO | C44: EMBASAMENTO | D44: PA01 | E44: PORTA | F44: 4 | G44: 1 | H44: =G44*F44 -> 4 | I44: 0.96 | J44: 2.13 | K44: 0.165 | L44: =((I44*K44)+(2*0.1*K44))*H44 -> 0.7656
B45: 4º PAVIMENTO | C45: EMBASAMENTO | D45: J01 | E45: JANELA | F45: 7 | G45: 1 | H45: =G45*F45 -> 7 | I45: =VLOOKUP(D45,'[1]RESUMO ESQ. '!$E$6:$L$71,5,FALSE) -> 0.5 | J45: =VLOOKUP(D45,'[1]RESUMO ESQ. '!$E$6:$L$71,6,FALSE) -> 0.73 | K45: 0.19 | L45: =((I45*K45)+(2*0.1*K45))*H45 -> 0.931
B46: 4º PAVIMENTO | C46: EMBASAMENTO | D46: J02 | E46: JANELA | F46: 3 | G46: 1 | H46: =G46*F46 -> 3 | I46: =VLOOKUP(D46,'[1]RESUMO ESQ. '!$E$6:$L$71,5,FALSE) -> 0.5 | J46: =VLOOKUP(D46,'[1]RESUMO ESQ. '!$E$6:$L$71,6,FALSE) -> 0.61 | K46: 0.19 | L46: =((I46*K46)+(2*0.1*K46))*H46 -> 0.399
...
